<mujoco model="brick">

    <worldbody>
        <body name="brick">
            <!-- six DOF for movement and rotation in all directions-->
            <joint name="slide_x" type="slide" pos="0 0 0" axis="1 0 0" damping="1" />
            <joint name="slide_y" type="slide" pos="0 0 0" axis="0 1 0" damping="1" />
            <joint name="slide_z" type="slide" pos="0 0 0" axis="0 0 1" damping="1" />
            <joint name="hinge_x" type="hinge" pos="0 0 0" axis="1 0 0" damping="1" />
            <joint name="hinge_y" type="hinge" pos="0 0 0" axis="0 1 0" damping="1" />
            <joint name="hinge_z" type="hinge" pos="0 0 0" axis="0 0 1" damping="1" />
            <geom type="box" size=".1 .3 .2" rgba=".9 0 0 1" />
        </body>
    </worldbody>

    <actuator>
        <!-- actuation for paddle DOFs-->
        <motor name="motor_x" joint="slide_x" gear="1" ctrlrange="-10 10" ctrllimited="true" />
        <motor name="motor_y" joint="slide_y" gear="1" ctrlrange="-10 10" ctrllimited="true" />
        <motor name="motor_z" joint="slide_z" gear="1" ctrlrange="-10 10" ctrllimited="true" />
        <motor name="rot_x" joint="hinge_x" gear="1" ctrlrange="-10 10" ctrllimited="true" />
        <motor name="rot_y" joint="hinge_y" gear="1" ctrlrange="-10 10" ctrllimited="true" />
        <motor name="rot_z" joint="hinge_z" gear="1" ctrlrange="-10 10" ctrllimited="true" />
    </actuator>
</mujoco>