<mujoco model="tableworld">
  <compiler angle="radian"/>
  <option integrator="implicitfast"/>
  <visual>
    <global azimuth="120" elevation="-20"/>
    <headlight diffuse="0.6 0.6 0.6" specular="0 0 0"/>
    <rgba haze="0.15 0.25 0.35 1"/>
  </visual>
  <statistic extent="0.8" center="0.3 0 0.4"/>
  <default class="main">
    <default class="/"/>
    <default class="rethink_mount_stationary/"/>
    <default class="rethink_mount_stationary/ur5e/">
      <default class="rethink_mount_stationary/ur5e/ur5e">
        <material shininess="0.25"/>
        <joint range="-6.28319 6.28319" armature="0.1"/>
        <site size="0.001 0.005 0.005" group="4" rgba="0.5 0.5 0.5 0.3"/>
        <general ctrlrange="-6.2831 6.2831" forcerange="-150 150" biastype="affine" gainprm="2000" biasprm="0 -2000 -400"/>
        <default class="rethink_mount_stationary/ur5e/size3">
          <default class="rethink_mount_stationary/ur5e/size3_limited">
            <joint range="-3.1415 3.1415"/>
            <general ctrlrange="-3.1415 3.1415"/>
          </default>
        </default>
        <default class="rethink_mount_stationary/ur5e/size1">
          <general forcerange="-28 28" gainprm="500" biasprm="0 -500 -100"/>
        </default>
        <default class="rethink_mount_stationary/ur5e/visual">
          <geom type="mesh" contype="0" conaffinity="0" group="2"/>
        </default>
        <default class="rethink_mount_stationary/ur5e/collision">
          <geom type="capsule" group="3"/>
          <default class="rethink_mount_stationary/ur5e/eef_collision">
            <geom type="cylinder"/>
          </default>
        </default>
      </default>
    </default>
  </default>
  <asset>
    <texture type="skybox" name="//unnamed_texture_0" builtin="gradient" rgb1="0.3 0.5 0.7" rgb2="0 0 0" width="512" height="3072"/>
    <texture type="2d" name="groundplane" builtin="checker" mark="edge" rgb1="0.2 0.3 0.4" rgb2="0.1 0.2 0.3" markrgb="0.8 0.8 0.8" width="300" height="300"/>
    <material name="groundplane" class="/" texture="groundplane" texuniform="true" texrepeat="5 5" reflectance="0.2"/>
    <material name="rethink_mount_stationary/ur5e/black" class="rethink_mount_stationary/ur5e/ur5e" rgba="0.033 0.033 0.033 1"/>
    <material name="rethink_mount_stationary/ur5e/jointgray" class="rethink_mount_stationary/ur5e/ur5e" rgba="0.278 0.278 0.278 1"/>
    <material name="rethink_mount_stationary/ur5e/linkgray" class="rethink_mount_stationary/ur5e/ur5e" rgba="0.82 0.82 0.82 1"/>
    <material name="rethink_mount_stationary/ur5e/urblue" class="rethink_mount_stationary/ur5e/ur5e" rgba="0.49 0.678 0.8 1"/>
    <mesh name="rethink_mount_stationary/pedestal" class="rethink_mount_stationary/" file="pedestal-5e7ab40dad67858f3d51b3d2d13720c271905995.stl"/>
    <mesh name="rethink_mount_stationary/ur5e/base_0" class="rethink_mount_stationary/ur5e/" file="base_0-d5328a99917358d9aa384f12743fe73698461d1c.obj"/>
    <mesh name="rethink_mount_stationary/ur5e/base_1" class="rethink_mount_stationary/ur5e/" file="base_1-d1c667ae5f87b9c900fdeadad850205153846396.obj"/>
    <mesh name="rethink_mount_stationary/ur5e/shoulder_0" class="rethink_mount_stationary/ur5e/" file="shoulder_0-89051b80580d45ef39cb220bf068742b01770552.obj"/>
    <mesh name="rethink_mount_stationary/ur5e/shoulder_1" class="rethink_mount_stationary/ur5e/" file="shoulder_1-50ba15e82459989cf7f17cba7b1aafbca2781206.obj"/>
    <mesh name="rethink_mount_stationary/ur5e/shoulder_2" class="rethink_mount_stationary/ur5e/" file="shoulder_2-29ad171bec79e2912abb81d250aaf5ff9a67bc60.obj"/>
    <mesh name="rethink_mount_stationary/ur5e/upperarm_0" class="rethink_mount_stationary/ur5e/" file="upperarm_0-16bfdf8d1b19d35ef0adbc4cf29ab0c7edb62dcf.obj"/>
    <mesh name="rethink_mount_stationary/ur5e/upperarm_1" class="rethink_mount_stationary/ur5e/" file="upperarm_1-c53724435bec35e1b608145457af767b038f4fd1.obj"/>
    <mesh name="rethink_mount_stationary/ur5e/upperarm_2" class="rethink_mount_stationary/ur5e/" file="upperarm_2-199e0d0c1baa55a078742ed298800ff26d072c09.obj"/>
    <mesh name="rethink_mount_stationary/ur5e/upperarm_3" class="rethink_mount_stationary/ur5e/" file="upperarm_3-62f2bba935d9ab94800a49bcb6ede7b0fa9dd071.obj"/>
    <mesh name="rethink_mount_stationary/ur5e/forearm_0" class="rethink_mount_stationary/ur5e/" file="forearm_0-7994229075bdd0e4a5c860ca174278ee8eda8229.obj"/>
    <mesh name="rethink_mount_stationary/ur5e/forearm_1" class="rethink_mount_stationary/ur5e/" file="forearm_1-c72848167eef89e0d9801ddd7da516e7e878776e.obj"/>
    <mesh name="rethink_mount_stationary/ur5e/forearm_2" class="rethink_mount_stationary/ur5e/" file="forearm_2-3a33518f421ed893ff9b0d759af07b0e5900e78c.obj"/>
    <mesh name="rethink_mount_stationary/ur5e/forearm_3" class="rethink_mount_stationary/ur5e/" file="forearm_3-54cad2556a94cdda04a7cef5c84554a7d9f3ab03.obj"/>
    <mesh name="rethink_mount_stationary/ur5e/wrist1_0" class="rethink_mount_stationary/ur5e/" file="wrist1_0-6876ccb9d0084054268dd6aec007e5a61aea6c2d.obj"/>
    <mesh name="rethink_mount_stationary/ur5e/wrist1_1" class="rethink_mount_stationary/ur5e/" file="wrist1_1-0f7e6640a9dfb98e58078997f5f82bd433879387.obj"/>
    <mesh name="rethink_mount_stationary/ur5e/wrist1_2" class="rethink_mount_stationary/ur5e/" file="wrist1_2-3f6dcae8c736e2c42db3746db7f24ac4516aaca7.obj"/>
    <mesh name="rethink_mount_stationary/ur5e/wrist2_0" class="rethink_mount_stationary/ur5e/" file="wrist2_0-fdb3f7bc360f8f37f6be6270c8b507291dc9b01c.obj"/>
    <mesh name="rethink_mount_stationary/ur5e/wrist2_1" class="rethink_mount_stationary/ur5e/" file="wrist2_1-258ca475798c530d954723dc29f3d67086ead0d9.obj"/>
    <mesh name="rethink_mount_stationary/ur5e/wrist2_2" class="rethink_mount_stationary/ur5e/" file="wrist2_2-c6734971531db7f2f09e746377aa9faccb69b192.obj"/>
    <mesh name="rethink_mount_stationary/ur5e/wrist3" class="rethink_mount_stationary/ur5e/" file="wrist3-a1fffb4f599e121fb18be40e087b6fd7fb164e59.obj"/>
  </asset>
  <worldbody>
    <geom name="floor" class="/" size="0 0 0.05" type="plane" material="groundplane"/>
    <site name="//unnamed_site_0" class="/" pos="0 0 0" size="1e-06"/>
    <camera name="top-right" class="/" pos="2.5 1.2 2.5" quat="0.47416 0.259035 0.403423 0.73846"/>
    <light name="//unnamed_light_0" class="/" pos="0 0 1.5" dir="0 0 -1" directional="true"/>
    <body name="table_left" pos="0 -0.6 0">
      <geom name="table_left_top" class="/" size="0.37 0.37 0.01" pos="0 0 0.7" type="box"/>
      <geom name="table_left_leg_1" class="/" size="0.01 0.7" pos="0.24 -0.24 0" type="cylinder"/>
      <geom name="table_left_leg_2" class="/" size="0.01 0.7" pos="0.24 0.24 0" type="cylinder"/>
      <geom name="table_left_leg_3" class="/" size="0.01 0.7" pos="-0.24 -0.24 0" type="cylinder"/>
      <geom name="table_left_leg_4" class="/" size="0.01 0.7" pos="-0.24 0.24 0" type="cylinder"/>
    </body>
    <body name="table_right" pos="0 0.6 0">
      <geom name="table_right_top" class="/" size="0.37 0.37 0.01" pos="0 0 0.7" type="box"/>
      <geom name="table_right_leg_1" class="/" size="0.01 0.7" pos="0.24 -0.24 0" type="cylinder"/>
      <geom name="table_right_leg_2" class="/" size="0.01 0.7" pos="0.24 0.24 0" type="cylinder"/>
      <geom name="table_right_leg_3" class="/" size="0.01 0.7" pos="-0.24 -0.24 0" type="cylinder"/>
      <geom name="table_right_leg_4" class="/" size="0.01 0.7" pos="-0.24 0.24 0" type="cylinder"/>
    </body>
    <body name="red_box" pos="0 -0.8 0.72" quat="0 0 1 0">
      <joint name="//unnamed_joint_0" type="free" limited="false" actuatorfrclimited="false"/>
      <geom name="//unnamed_geom_11" class="/" size="0.05 0.05 0.01" type="box" rgba="1 0 0 1"/>
    </body>
    <body name="yellow box" pos="0.1 -0.3 0.72">
      <joint name="//unnamed_joint_1" type="free" limited="false" actuatorfrclimited="false"/>
      <geom name="//unnamed_geom_12" class="/" size="0.05 0.05 0.01" type="box" rgba="1 1 0 1"/>
    </body>
    <body name="cyan box" pos="-0.1 -0.7 0.72">
      <joint name="//unnamed_joint_2" type="free" limited="false" actuatorfrclimited="false"/>
      <geom name="//unnamed_geom_13" class="/" size="0.05 0.05 0.01" type="box" rgba="0 1 1 1"/>
    </body>
    <body name="purple box" pos="-0.2 0.5 0.72">
      <joint name="//unnamed_joint_3" type="free" limited="false" actuatorfrclimited="false"/>
      <geom name="//unnamed_geom_14" class="/" size="0.05 0.05 0.01" type="box" rgba="1 0 1 1"/>
    </body>
    <body name="rethink_mount_stationary/">
      <body name="rethink_mount_stationary/base" pos="0 0 0.903">
        <site name="rethink_mount_stationary//unnamed_site_0" class="rethink_mount_stationary/" pos="0 0 0" size="1e-06"/>
        <body name="rethink_mount_stationary/controller_box">
          <inertial pos="-0.325 0 -0.38" mass="46.64" diaginertia="1.71363 1.27988 0.809981"/>
          <geom name="rethink_mount_stationary/controller_box_col" class="rethink_mount_stationary/" size="0.11 0.2 0.265" pos="-0.325 0 -0.38" type="box" rgba="0 0 0 0"/>
        </body>
        <body name="rethink_mount_stationary/pedestal_feet">
          <inertial pos="-0.1225 0 -0.758" mass="167.09" diaginertia="8.16095 9.59375 15.0785"/>
          <geom name="rethink_mount_stationary/pedestal_feet_col" class="rethink_mount_stationary/" size="0.385 0.35 0.155" pos="-0.1225 0 -0.758" type="box" rgba="0 0 0 0"/>
        </body>
        <body name="rethink_mount_stationary/torso">
          <inertial pos="0 0 0" mass="0.0001" diaginertia="1e-08 1e-08 1e-08"/>
          <geom name="rethink_mount_stationary/torso_vis" class="rethink_mount_stationary/" size="0.05 0.05 0.05" pos="0 0 -0.05" type="box" contype="0" conaffinity="0" group="1" rgba="0.2 0.2 0.2 0"/>
        </body>
        <body name="rethink_mount_stationary/pedestal">
          <inertial pos="0 0 0" quat="0.659267 -0.259505 -0.260945 0.655692" mass="60.864" diaginertia="6.0869 5.81635 4.20915"/>
          <geom name="rethink_mount_stationary/pedestal_vis" class="rethink_mount_stationary/" type="mesh" contype="0" conaffinity="0" group="1" rgba="0.2 0.2 0.2 1" mesh="rethink_mount_stationary/pedestal"/>
          <geom name="rethink_mount_stationary/pedestal_col" class="rethink_mount_stationary/" size="0.18 0.31" pos="-0.02 0 -0.29" type="cylinder" contype="0" conaffinity="0" rgba="0.2 0.2 0.2 0"/>
        </body>
        <body name="rethink_mount_stationary/ur5e/">
          <light name="rethink_mount_stationary/ur5e/spotlight" class="rethink_mount_stationary/ur5e/" target="rethink_mount_stationary/ur5e/wrist_2_link" pos="0 -1 2" dir="0 0 -1" mode="targetbodycom"/>
          <body name="rethink_mount_stationary/ur5e/base" childclass="rethink_mount_stationary/ur5e/ur5e" quat="0.707107 0 0 0.707107">
            <inertial pos="0 0 0" mass="4" diaginertia="0.00443333 0.00443333 0.0072"/>
            <geom name="rethink_mount_stationary/ur5e//unnamed_geom_0" class="rethink_mount_stationary/ur5e/visual" material="rethink_mount_stationary/ur5e/black" mesh="rethink_mount_stationary/ur5e/base_0"/>
            <geom name="rethink_mount_stationary/ur5e//unnamed_geom_1" class="rethink_mount_stationary/ur5e/visual" material="rethink_mount_stationary/ur5e/jointgray" mesh="rethink_mount_stationary/ur5e/base_1"/>
            <body name="rethink_mount_stationary/ur5e/shoulder_link" pos="0 0 0.163">
              <inertial pos="0 0 0" mass="3.7" diaginertia="0.0102675 0.0102675 0.00666"/>
              <joint name="rethink_mount_stationary/ur5e/shoulder_pan_joint" class="rethink_mount_stationary/ur5e/size3" pos="0 0 0" axis="0 0 1"/>
              <geom name="rethink_mount_stationary/ur5e//unnamed_geom_2" class="rethink_mount_stationary/ur5e/visual" material="rethink_mount_stationary/ur5e/urblue" mesh="rethink_mount_stationary/ur5e/shoulder_0"/>
              <geom name="rethink_mount_stationary/ur5e//unnamed_geom_3" class="rethink_mount_stationary/ur5e/visual" material="rethink_mount_stationary/ur5e/black" mesh="rethink_mount_stationary/ur5e/shoulder_1"/>
              <geom name="rethink_mount_stationary/ur5e//unnamed_geom_4" class="rethink_mount_stationary/ur5e/visual" material="rethink_mount_stationary/ur5e/jointgray" mesh="rethink_mount_stationary/ur5e/shoulder_2"/>
              <geom name="rethink_mount_stationary/ur5e//unnamed_geom_5" class="rethink_mount_stationary/ur5e/collision" size="0.06 0.06" pos="0 0 -0.04"/>
              <body name="rethink_mount_stationary/ur5e/upper_arm_link" pos="0 0.138 0" quat="0.707107 0 0.707107 0">
                <inertial pos="0 0 0.2125" mass="8.393" diaginertia="0.133886 0.133886 0.0151074"/>
                <joint name="rethink_mount_stationary/ur5e/shoulder_lift_joint" class="rethink_mount_stationary/ur5e/size3" pos="0 0 0" axis="0 1 0"/>
                <geom name="rethink_mount_stationary/ur5e//unnamed_geom_6" class="rethink_mount_stationary/ur5e/visual" material="rethink_mount_stationary/ur5e/linkgray" mesh="rethink_mount_stationary/ur5e/upperarm_0"/>
                <geom name="rethink_mount_stationary/ur5e//unnamed_geom_7" class="rethink_mount_stationary/ur5e/visual" material="rethink_mount_stationary/ur5e/black" mesh="rethink_mount_stationary/ur5e/upperarm_1"/>
                <geom name="rethink_mount_stationary/ur5e//unnamed_geom_8" class="rethink_mount_stationary/ur5e/visual" material="rethink_mount_stationary/ur5e/jointgray" mesh="rethink_mount_stationary/ur5e/upperarm_2"/>
                <geom name="rethink_mount_stationary/ur5e//unnamed_geom_9" class="rethink_mount_stationary/ur5e/visual" material="rethink_mount_stationary/ur5e/urblue" mesh="rethink_mount_stationary/ur5e/upperarm_3"/>
                <geom name="rethink_mount_stationary/ur5e//unnamed_geom_10" class="rethink_mount_stationary/ur5e/collision" size="0.06 0.06" pos="0 -0.04 0" quat="0.707107 0.707107 0 0"/>
                <geom name="rethink_mount_stationary/ur5e//unnamed_geom_11" class="rethink_mount_stationary/ur5e/collision" size="0.05 0.2" pos="0 0 0.2"/>
                <body name="rethink_mount_stationary/ur5e/forearm_link" pos="0 -0.131 0.425">
                  <inertial pos="0 0 0.196" mass="2.275" diaginertia="0.0311796 0.0311796 0.004095"/>
                  <joint name="rethink_mount_stationary/ur5e/elbow_joint" class="rethink_mount_stationary/ur5e/size3_limited" pos="0 0 0" axis="0 1 0"/>
                  <geom name="rethink_mount_stationary/ur5e//unnamed_geom_12" class="rethink_mount_stationary/ur5e/visual" material="rethink_mount_stationary/ur5e/urblue" mesh="rethink_mount_stationary/ur5e/forearm_0"/>
                  <geom name="rethink_mount_stationary/ur5e//unnamed_geom_13" class="rethink_mount_stationary/ur5e/visual" material="rethink_mount_stationary/ur5e/linkgray" mesh="rethink_mount_stationary/ur5e/forearm_1"/>
                  <geom name="rethink_mount_stationary/ur5e//unnamed_geom_14" class="rethink_mount_stationary/ur5e/visual" material="rethink_mount_stationary/ur5e/black" mesh="rethink_mount_stationary/ur5e/forearm_2"/>
                  <geom name="rethink_mount_stationary/ur5e//unnamed_geom_15" class="rethink_mount_stationary/ur5e/visual" material="rethink_mount_stationary/ur5e/jointgray" mesh="rethink_mount_stationary/ur5e/forearm_3"/>
                  <geom name="rethink_mount_stationary/ur5e//unnamed_geom_16" class="rethink_mount_stationary/ur5e/collision" size="0.055 0.06" pos="0 0.08 0" quat="0.707107 0.707107 0 0"/>
                  <geom name="rethink_mount_stationary/ur5e//unnamed_geom_17" class="rethink_mount_stationary/ur5e/collision" size="0.038 0.19" pos="0 0 0.2"/>
                  <body name="rethink_mount_stationary/ur5e/wrist_1_link" pos="0 0 0.392" quat="0.707107 0 0.707107 0">
                    <inertial pos="0 0.127 0" mass="1.219" diaginertia="0.0025599 0.0025599 0.0021942"/>
                    <joint name="rethink_mount_stationary/ur5e/wrist_1_joint" class="rethink_mount_stationary/ur5e/size1" pos="0 0 0" axis="0 1 0"/>
                    <geom name="rethink_mount_stationary/ur5e//unnamed_geom_18" class="rethink_mount_stationary/ur5e/visual" material="rethink_mount_stationary/ur5e/black" mesh="rethink_mount_stationary/ur5e/wrist1_0"/>
                    <geom name="rethink_mount_stationary/ur5e//unnamed_geom_19" class="rethink_mount_stationary/ur5e/visual" material="rethink_mount_stationary/ur5e/urblue" mesh="rethink_mount_stationary/ur5e/wrist1_1"/>
                    <geom name="rethink_mount_stationary/ur5e//unnamed_geom_20" class="rethink_mount_stationary/ur5e/visual" material="rethink_mount_stationary/ur5e/jointgray" mesh="rethink_mount_stationary/ur5e/wrist1_2"/>
                    <geom name="rethink_mount_stationary/ur5e//unnamed_geom_21" class="rethink_mount_stationary/ur5e/collision" size="0.04 0.07" pos="0 0.05 0" quat="0.707107 0.707107 0 0"/>
                    <body name="rethink_mount_stationary/ur5e/wrist_2_link" pos="0 0.127 0">
                      <inertial pos="0 0 0.1" mass="1.219" diaginertia="0.0025599 0.0025599 0.0021942"/>
                      <joint name="rethink_mount_stationary/ur5e/wrist_2_joint" class="rethink_mount_stationary/ur5e/size1" pos="0 0 0" axis="0 0 1"/>
                      <geom name="rethink_mount_stationary/ur5e//unnamed_geom_22" class="rethink_mount_stationary/ur5e/visual" material="rethink_mount_stationary/ur5e/black" mesh="rethink_mount_stationary/ur5e/wrist2_0"/>
                      <geom name="rethink_mount_stationary/ur5e//unnamed_geom_23" class="rethink_mount_stationary/ur5e/visual" material="rethink_mount_stationary/ur5e/urblue" mesh="rethink_mount_stationary/ur5e/wrist2_1"/>
                      <geom name="rethink_mount_stationary/ur5e//unnamed_geom_24" class="rethink_mount_stationary/ur5e/visual" material="rethink_mount_stationary/ur5e/jointgray" mesh="rethink_mount_stationary/ur5e/wrist2_2"/>
                      <geom name="rethink_mount_stationary/ur5e//unnamed_geom_25" class="rethink_mount_stationary/ur5e/collision" size="0.04 0.06" pos="0 0 0.04"/>
                      <geom name="rethink_mount_stationary/ur5e//unnamed_geom_26" class="rethink_mount_stationary/ur5e/collision" size="0.04 0.04" pos="0 0.02 0.1" quat="0.707107 0.707107 0 0"/>
                      <body name="rethink_mount_stationary/ur5e/wrist_3_link" pos="0 0 0.1">
                        <inertial pos="0 0.0771683 0" quat="0.707107 0 0 0.707107" mass="0.1889" diaginertia="0.000132134 9.90863e-05 9.90863e-05"/>
                        <joint name="rethink_mount_stationary/ur5e/wrist_3_joint" class="rethink_mount_stationary/ur5e/size1" pos="0 0 0" axis="0 1 0"/>
                        <geom name="rethink_mount_stationary/ur5e//unnamed_geom_27" class="rethink_mount_stationary/ur5e/visual" material="rethink_mount_stationary/ur5e/linkgray" mesh="rethink_mount_stationary/ur5e/wrist3"/>
                        <geom name="rethink_mount_stationary/ur5e//unnamed_geom_28" class="rethink_mount_stationary/ur5e/eef_collision" size="0.04 0.02" pos="0 0.08 0" quat="0.707107 0.707107 0 0"/>
                        <site name="rethink_mount_stationary/ur5e/attachment_site" pos="0 0.1 0" quat="-0.707107 0.707107 0 0"/>
                      </body>
                    </body>
                  </body>
                </body>
              </body>
            </body>
          </body>
        </body>
      </body>
    </body>
  </worldbody>
  <actuator>
    <general name="rethink_mount_stationary/ur5e/shoulder_pan" class="rethink_mount_stationary/ur5e/size3" joint="rethink_mount_stationary/ur5e/shoulder_pan_joint"/>
    <general name="rethink_mount_stationary/ur5e/shoulder_lift" class="rethink_mount_stationary/ur5e/size3" joint="rethink_mount_stationary/ur5e/shoulder_lift_joint"/>
    <general name="rethink_mount_stationary/ur5e/elbow" class="rethink_mount_stationary/ur5e/size3_limited" joint="rethink_mount_stationary/ur5e/elbow_joint"/>
    <general name="rethink_mount_stationary/ur5e/wrist_1" class="rethink_mount_stationary/ur5e/size1" joint="rethink_mount_stationary/ur5e/wrist_1_joint"/>
    <general name="rethink_mount_stationary/ur5e/wrist_2" class="rethink_mount_stationary/ur5e/size1" joint="rethink_mount_stationary/ur5e/wrist_2_joint"/>
    <general name="rethink_mount_stationary/ur5e/wrist_3" class="rethink_mount_stationary/ur5e/size1" joint="rethink_mount_stationary/ur5e/wrist_3_joint"/>
  </actuator>
</mujoco>
