<mujoco model="pushworld">
  <compiler inertiafromgeom="true" angle="radian" coordinate="local"/>
  <option gravity="0 0 0" integrator="Euler" />

  <default>
    <joint armature='0.04' damping="1" limited="true"/>
    <geom friction=".8 .1 .1" density="300" margin="0.002" condim="1" contype="0" conaffinity="0"/>
  </default>

  <worldbody>
    <light diffuse=".5 .5 .5" pos="0 0 3" dir="0 0 -1"/>
    <geom name="table" type="plane" pos="0 0.5 -0.325" size="1 1 0.1" contype="1" conaffinity="1"/>

    <!--<body name="object" pos="0.55 -0.3 -0.275" >-->
    <body name="object" pos="0.45 -0.05 -0.275" >
      <geom rgba=".9 0 0 0" type="sphere" size="0.05 0.05 0.05" density="0.00001" conaffinity="0"/>
      <geom rgba=".9 0 0 1" type="cylinder" size="0.05 0.05 0.05" density="0.00001" contype="1" conaffinity="0"/>
      <joint name="obj_slidey" type="slide" pos="0 0 0" axis="0 1 0" range="-10.3213 10.3" damping="0.5"/>
      <joint name="obj_slidex" type="slide" pos="0 0 0" axis="1 0 0" range="-10.3213 10.3" damping="0.5"/>
    </body>
  </worldbody>
</mujoco>